model
name = monu7
size = 125 126 125
scale = 0.05
origin = -y
shell = Outline 0.25
material type = toon, lighting = smooth, deform = 1 1
  colors = A:#CDA96F B:#62C3B6 C:#C5B798 D:#786D52 E:#D99102 F:#F67912 G:#7EA29D H:#3B3B3B I:#524A38 J:#997E52 K:#997F4C L:#848484
material type = basic, lighting = smooth, roughness = 0, refractionRatio = 1, side = back
  colors = Outline:#000
voxels
12-5(5(109C16-)109C4-125C14887-)3(5(109C16-)109C4-125C45-3F122-3F14714-)5(109C16-)109C4-125C6(14887-5(4C60B45C16-)4C60-45C4-16C60-49C)5-3F122-3F7297-7(32A93-)32A6550-5(4C60B45C16-)4C60-45C4-16C60-49C5-3F122-3F889-9A6399-6(32A93-)A30-A93-A30-A6550-5(4C7B7A46B45C16-)4C7-7A46-45C4-16C7-7A46-49C5-3F15-7A100-3F15-6(7A118-)2(7A117-9A117-4(7G118-)7G5775-6(32A93-)A30-A93-A30-A6550-5(4C7B7A46B45C16-)4C7-7A46-45C4-16C7-7A46-49C23-7(7A118-))7A117-9A117-4(7G118-)7G120-2(3G122-)3G5402-6(32A93-)A30-A93-A30-A6550-5(4C7B7A46B45C16-)4C7-7A46-45C4-16C7-7A46-49C23-7A4(119-6A)3(118-7A)2(117-9A117-4(7G118-)7G120-2(3G122-)3G5402-6(32A93-)A30-A93-A30-A6550-5(4C7B7A75B16C16-)4C7-7A75-16C4-16C7-7A75-20C23-7(7A118-)7A)117-9A117-4(7G118-)7G5775-6(32A93-)A5-20A5-A93-A5-20A5-A6550-5(4C7B7A75B16C16-)4C7-7A75-16C4-16C7-7A75-20C23-7A4(118-3A-3A)3(118-7A)117-9A117-4(7G118-)7G5775-6(7A18-7A93-)A5-A18-7A93-A5-A18-12(7A118-)A5-A118-A5-A4925-5(4C89B16C16-)4C89-16C4-16C89-20C1022-9A6399-4(6(7A18-7A93-)A5-A18-7A93-A5-A18-12(7A118-)A5-A118-A5-A4925-5(4C89B16C16-)4C89-16C4-16C89-20C7430-)6(7A18-7A93-)A5-A18-7A93-A5-A18-12(7A118-)A5-A118-A5-A4925-5(4C54B27A8B16C16-)4C54-27A8-16C4-16C54-27A8-20C70-58(27A98-)6(27A83-7A8-)2(27A83-A5-A8-)9(27A98-)27A108-2(7A118-)A5-A118-A5-A4925-5(4C54B6A20CA8B16C16-)4C54-6A20CA8-16C4-16C54-A25BA8-20C70-58(A25BA98-)3(6(A25BA83-7A8-)2(A25BA83-A5-A8-)9(A25BA98-)A9-7A9-A108-2(7A118-)A5-A118-A5-A4925-5(4C24B6F24B6A20CA8B16C16-)4C24-6F24-6A20CA8-16C4-16C24-6F24-A25BA8-20C40-6F11(24-A25BA69-5F)3(24-A25BA71-3F)24-44(A25BA98-))6(A25BA83-7A8-)2(A25BA83-A5-A8-)9(A25BA98-)A25-A4860-3H122-H-H122-3H302-5(4C24B6F24B6A20CA8B16C16-)4C24-6F24-6A20CA8-16C4-16C24-6F24-A25BA8-20C40-6F11(24-A25BA69-5F)24-A25BA71-3F24-46(A25BA98-)6(A25BA83-7A8-)2(A25BA83-A5-A8-)9(A25BA98-)A25-A4860-3H122-H-H122-3H302-5(4C24B6F24B6A20CA8B16C16-)4C24-6F24-6A20CA8-16C4-16C24-6F24-A25BA8-20C40-6F7(24-A25BA69-5F)5(24-A25BA71-3F)24-46(A25BA98-)6(A25BA83-7A8-)2(A25BA83-A5-A8-)9(A25BA98-)A25-A4860-3H122-H-H122-3H302-5(4C24B6F24B6A20CA8B16C16-)4C24-6F24-6A20CA8-16C4-16C24-6F24-A25BA8-20C6-3F31-6F24-A25BA34-3F31-3(6F24-A25BA68-)6F3(24-A25BA69-5F)5(24-A25BA71-3F)24-46(A25BA98-)6(A25BA83-7A8-)2(A25BA83-A5-A8-)9(A25BA98-)A25-A4986-L428-5(4C24B6F24B6A20CA8B16C16-)4C24-6F24-6A20CA8-16C4-16C24-6F24-A25BA8-20C6-3F31-6F24-A25BA34-3F31-3(6F24-A25BA68-)6F24-54(A25BA98-)6(A25BA83-7A8-)2(A25BA83-A5-A8-)9(A25BA98-)A25-A4986-L428-5(4C54B6A20CA8B16C16-)4C54-6A20CA8-16C4-16C54-A25BA8-20C6-3F61-A25BA34-3F61-57(A25BA98-)6(A25BA83-7A8-)2(A25BA83-A5-A8-)9(A25BA98-)A25-A4986-L428-4(4C15B40A25CA8B16C16-)4C15B39A26CA8B16C16-4C15-39A26CA8-16C4-16C15-40A9B7A9BA8-20C31-8(40A9B7A9BA59-)8E32A9B7A9BA59-8E49(32A9B7A9BA67-)32A6(9B7A9BA74-6A3-7A3-6A)2(9B7A9BA74-6A3-A5-A3-6A)6(9B7A9BA74-6A13-6A)2(9B7A9BA74-25A)9B7A9BA74-28A6-7A9-A74-3(28A6-7A84-)28A6-16(7A118-)7A2(112-13A)10(118-7A)2(118-7K118-7A)118-7A371-L428-4(4C15B40A25CA8B16C16-)4C15B39A26CA8B16C16-4C15-39A26CA8-16C4-16C15-40A9B7A9BA8-20C31-8(40A9B7A9BA59-)8E32A9B7A9BA59-8E48(32A9B7A9BA67-)A5B26A9B7A9BA67-A5-B25A6(9B7A9BA73-B6A3-7A3-6A)2(9B7A9BA73-B6A3-A5-A3-6A)6(9B7A9BA73-B6A13-6A)3(9B7A9BA73-B25A)3B6-7A9-A73-2(B25A3B6-7A83-)29B18(6-7A111-B)13A111-7B7A2(112-13A)8(118-7A)2(118-K5AK118-7A)118-7A119-5H247-L372-5H51-4(4C15B40A25CA8B16C16-)4C15B39A26CA8B16C16-4C15-39A26CA8-16C4-16C15-40A9B7A9BA8-20C31-8(40A9B7A9BA59-)8E32A9B7A9BA59-8E2(32A9B7A9BA63-3F-)46(32A9B7A9BA67-)A5B26A9B7A9BA67-A5-B25A6(9B7A9BA73-B6A3-7A3-6A)2(9B7A9BA73-B6A3-A5-A3-6A)6(9B7A9BA73-B6A13-6A)3(9B7A9BA73-B25A)3B6-7A9-A73-2(B25A3B6-7A83-)29B18(6-7A111-B)13A111-7B2(7A118-)7A113-12A7(118-7A)2(118-K5AK118-7A)118-7A119-5H113-2(2(3H5-)3H106-)2(3H5-)3H114-3H121-H3-H51-4(4C2B5F8B40A25CA8B16C16-)4C2B5F8B39A26CA8B16C16-4C2-5F8-39A26CA8-16C4-16C2-5F8-40A9B7A9BA8-20C18-5F2(8-40A9B7A9BA48-3F)8-6(40A9B7A9BA59-)8E32A9B7A9BA59-8E2(32A9B7A9BA63-3F-)33(32A9B7A9BA67-)32A5(9B7A9BA68-31A)7(9B7A9BA67-32A)9B7A9BA67-A5B26A9B7A9BA67-A5-B25A6(9B7A9BA73-B6A3-7A3-6A)2(9B7A9BA73-B6A3-A5-A3-6A)6(9B7A9BA73-B6A13-6A)3(9B7A9BA73-B25A)3B6-7A9-A73-2(B25A3B6-7A83-)29B18(6-7A111-B)13A111-7B2(7A118-)7A113-12A7(118-7A)2(118-K5AK118-7A)118-7A119-5H113-2(3H5-)3H109-5L3H5L109-2(3H5-)3H114-3H121-2(H-)H51-4(4C2B5F8B40A25CA8B16C16-)4C2B5F8B39A26CA8B16C16-4C2-5F8-39A26CA8-16C4-16C2-5F8-40A9B7A9BA8-20C18-5F2(8-40A9B7A9BA48-3F)8-6(40A9B7A9BA59-)8E32A9B7A9BA59-8E2(32A9B7A9BA63-3F-)46(32A9B7A9BA67-)A5B26A9B7A9BA67-A5-B25A6(9B7A9BA73-B6A3-7A3-6A)2(9B7A9BA73-B6A3-A5-A3-6A)6(9B7A9BA73-B6A13-6A)3(9B7A9BA73-B25A)3B6-7A9-A73-2(B25A3B6-7A83-)29B18(6-7A111-B)13A111-7B2(7A118-)7A113-12A7(118-7A)2(118-K5AK118-7A)118-7A119-5H113-2(2(3H5-)3H106-)2(3H5-)3H114-3H121-H3-H51-4(4C2B5F8B40A25CA8B16C16-)4C2B5F8B39A26CA8B16C16-4C2-5F8-39A26CA8-16C4-16C2-5F8-40A9B7A9BA8-20C18-5F2(8-40A9B7A9BA48-3F)8-6(40A9B7A9BA59-)8E32A9B7A9BA59-8E48(32A9B7A9BA67-)A5B26A9B7A9BA67-A5-B25A6(9B7A9BA73-B6A3-7A3-6A)2(9B7A9BA73-B6A3-A5-A3-6A)6(9B7A9BA73-B6A13-6A)3(9B7A9BA73-B25A)3B6-7A9-A73-2(B25A3B6-7A83-)29B18(6-7A111-B)13A111-7B7A2(112-13A)8(118-7A)2(118-K5AK118-7A)118-7A119-5H247-L372-5H51-4(4C2B5F8B40A25CA8B16C16-)4C2B5F8B39A26CA8B16C16-4C2-5F8-39A26CA8-16C4-16C2-5F8-40A9B7A9BA8-20C18-5F8-8(40A9B7A9BA59-)8E32A9B7A9BA59-8E48(32A9B7A9BA67-)A5B26A9B7A9BA67-A5-26A6(9B7A9BA74-6A3-7A3-6A)2(9B7A9BA74-6A3-A5-A3-6A)6(9B7A9BA74-6A13-6A)2(9B7A9BA74-25A)9B7A9BA74-28A6-7A9-A74-3(28A6-7A84-)28A6-16(7A118-)7A2(112-13A)10(118-7A)2(118-7K118-7A)118-7A371-L428-4(4C2B5F8B40A25CA8B16C16-)4C2B5F8B39A26CA8B16C16-4C2-5F8-39A26CA8-16C4-16C2-5F8-40A25BA8-20C18-5F8-8(40A25BA59-)31E9A25BA59-31E19(9A25BA90-)8E24(A25BA98-)4(A25BA67-7A24-)A25BA67-A5BA24-A25BA67-A5-A24-2(A25BA98-)4(A25BA83-7A8-)2(A25BA83-A5-A8-)9(A25BA98-)A2(25-A1608-7A118-A5BA119-A3-A120-A3-A121-3A2873-L428-4(4C15B40A25CA8B16C16-)4C15B39A26CA8B16C16-4C15-39A26CA8-16C4-16C15-40A25BA8-20C31-8(40A25BA59-)31E9A25BA59-31E19(9A25BA90-)8E11(A25BA92-3F3-)7(A25BA93-2F3-)6(A25BA98-)4(A25BA67-7A24-)A25BA67-A5BA24-A25BA67-A5-A24-2(A25BA98-)3(A25BA83-7A8-)A25BA83-7A2(9-25BA83-A5-A)9-25BA99-8(25BA98-A))25-A1608-7A118-A5BA119-A3-A120-A3-A121-3A2873-L428-5(11C8BA64CA8B16C16-)11C8-A64CA8-16C4-23C8-A30C9A25BA8-20C31-8(40A25BA59-)31E9A25BA59-31E19(9A25BA90-)8E6(A25BA92-3F3-)2(A25BA98-)2(4(A25B99-)12(A25BA98-)4(A25BA67-7A24-)A25BA67-A5BA24-A25BA67-A5-A24-2(A25BA98-)3(A25BA83-7A8-)A25BA83-7A2(9-25BA83-A5-A)9-25BA99-8(25BA98-A)25-A1608-7A118-A5BA119-A3-A120-A3-A121-3A2747-3H122-H-H122-3H302-5(11C8BA64CA8B16C16-)11C8-A64CA8-16C4-23C8-A30C9A25BA8-20C31-8(40A25BA59-)31E9A25BA59-31E19(9A25BA90-)8E8(A25BA98-))4(A25B99-)12(A25BA98-)4(A25BA67-7A24-)A25BA67-A5BA24-A25BA67-A5-A24-2(A25BA98-)3(A25BA83-7A8-)A25BA83-7A2(9-25BA83-A5-A)9-25BA99-8(25BA98-A)25-A1608-7A118-A5BA119-A3-A120-A3-A121-3A2747-3H122-H-H122-3H302-5(11C8BA64CA8B16C16-)11C8-A64CA8-16C4-23C8-A30C9A25BA8-20C3-2(5F23-40A25BA31-)5F23-6(40A25BA59-)31E9A25BA59-31E2(9A25BA62-3F25-)17(9A25BA90-)8E8(A25BA98-)4(A25B99-)12(A25BA98-)4(A25BA67-7A24-)A25BA67-A5BA24-A25BA67-A5-A24-4(A25BA98-)A25BA83-7A8-A25BA83-7A2(9-25BA83-A5-A)9-25BA99-8(25BA98-A)9-7A9-A108-2(7A118-)A5BA118-A5BA119-9(5B120-)5B3676-5(11C8BA64CA8B16C16-)11C8-A64CA8-16C4-23C8-A30C9A25BA8-20C3-2(5F23-40A25BA31-)5F23-6(40A25BA59-)31E9A25BA59-31E2(9A25BA62-3F25-)17(9A25BA90-)8E8(A25BA98-)4(A25B99-)12(A25BA98-)4(A25BA67-7A24-)A25BA67-A5BA24-A25BA67-A5-A24-4(A25BA98-)A25BA83-7A8-A25BA83-7A2(9-25BA83-A5-A)9-25BA99-8(25BA98-A)9-7A9-A108-2(7A118-)A5BA118-A5-A4925-5(11C8BA64CA8B16C16-)11C8-A64CA8-16C4-23C8-A30C9A25BA8-20C3-2(5F23-40A25BA31-)5F23-6(40A25BA59-)31E9A25BA59-31E2(9A25BA62-3F19-4F2-)17(9A25BA90-)8E8(A25BA98-)4(A25B99-)12(A25BA98-)4(A25BA67-7A24-)A25BA67-A5BA24-A25BA67-A5-A24-4(A25BA98-)A25BA83-7A8-A25BA83-7A2(9-25BA83-A5-A)9-25BA99-8(25BA98-A)9-7A9-A108-2(7A118-)A5BA118-A5-A4925-5(11C8BA64CA8B16C16-)11C8-A64CA8-16C4-23C8-A30C35A8-20C3-2(5F23-66A31-)5F23-6(66A59-)31E35A59-31E2(35A84-4F2-)3(35A85-3F2-)5(35A86-2F2-)9(35A90-)8E8(27A98-)4(18A107-)12(27A98-)4(27A67-7A24-)27A67-A5BA24-27A67-A5-A24-4(27A98-)27A83-7A8-27A83-7A2(14-21A83-A5-A)14-21A104-21A8(98-27A)108-2(7A118-)A5BA118-A5-A4925-5(11C8BA64CA8B16C16-)11C8-A64CA8-16C4-23C8-A30C25A9CA8-20C3-2(5F23-66A31-)5F23-6(66A59-)31E35A59-31E2(35A84-4F2-)3(35A85-3F2-)5(35A86-2F2-)35A90-25A10E90-7(25A100-)18E24(7A118-)4(7A77-7A34-)7A77-A5BA34-7A77-A5-A34-4(7A118-)2(7A93-7A18-)2(7A93-A5-A18-)12(7A118-)A5BA118-A5-A4925-5(11C8BA64CA8B16C16-)11C8-A64CA8-16C4-23C8-A30C25A9CA8-20C31-8(66A59-)2(31E35A59-)2(17D8-4F2-35A59-)3(17D9-3F2-35A59-)5(17D14-35A59-)17D14-25A10E59-17D14-25A69-17I14-25A69-17D14-5(25A100-)18E24(7A118-)7A77-7A4(34-7A77-A5BA)34-7A77-A5-A34-4(7A118-)2(7A93-7A18-)2(7A93-A5-A18-)12(7A118-)A5BA118-A5-A4925-5(11C8BA64CA8B16C16-)11C7-BA64CA8-16C4-23C7-BA30C25A9CA8-20C30-8(B66A58-)2(B31E35A58-)2B16D14-35A60-9(15BD14-35A59-D)15BD14-25A10E59-D15BD14-25A69-I15BI14-25A69-D8-5B2-D14-5(25A78-5B17-)18E29(7A78-5B35-)21(7A118-)A5BA118-A5-A4925-5(11C8BA64CA8B16C16-)11C7-BA64CA8-16C4-23C7-BA30C25A9CA8-20C30-8(B66A58-)2(B31E35A58-)2B16D14-35A60-9(15BD14-35A59-D)15BD14-25A10E59-D15BD14-25A69-I15BI14-25A69-D15-D14-5(25A100-)18E7A114-2F2-39(7A118-)7A4(119-6A)5(118-7A)118-A5BA118-A5-A4925-5(11C8BA64CA8B16C16-)11C7-BA64CA8-16C4-23C7-BA30C25A9CA8-20C30-8(B66A58-)2(B31E35A58-)2B16D14-35A60-5(15BD14-35A59-D)3(15BD14-35A60-)15BD14-35A59-D15BD14-25A10E59-D15BD14-25A69-I15BI14-25A69-D15-D14-5(25A100-)18E7A114-2F2-49(7A118-)A5BA118-A5-A4925-5(11C8BA64CA8B16C16-)11C7-BA64CA8-16C4-23C7-BA30C25A9CA8-20C17-2(5F8-B66A45-)5F8-6(B66A58-)2(B31E35A58-)2B16D14-35A60-9(15BD14-35A59-D)15BD14-25A10E59-D15BD14-25A69-I15BI14-25A69-D15-D14-5(25A100-)18E50(7A118-)A5BA118-A5-A4925-5(11C8B10A55CA8B16C16-)11C7-B10A55CA8-16C4-23C7-B10A21C8A26CA8-20C17-2(5F8-B66A45-)5F8-6(B66A58-)2(B31E35A58-)2B16D14-35A60-9(15BD14-35A59-D)15BD14-25A10E59-D15BD14-25A69-I15BI14-25A69-D15-D14-5(25A100-)18E28(7A118-)A5BA21(118-7A)118-A5BA118-A5-A4925-5(11C8B11A54CA8B16C16-)11C8-11A13C7-34CA8-16C4-23C8-11A13C7-8A26CA8-20C17-2(5F9-66A45-)5F9-6(66A59-)10E7A14E35A59-31E7(35A59-17D14-)3(35A59-2(5D-)5D14-)35A59-17D14-7A28E59-17D14-7A87-17I14-7A87-17D14-5(7A118-)7E2886-5(7A118-)A5BA118-A5BA119-20(5B120-)5B5051-5(11C18BA54CA8B16C16-)11C18-A54CA8-16C4-23C18-A20C8A26CA8-20C17-2(5F19-7A7-7D35A45-)5F19-7(7A7-7D35A69-)7E7-11(7D35A83-)7D7A28E83-7(7D7A111-)7D7E111-22(7D118-)5(7D18-7A93-)7D18-A5BA93-7D18-A5-A93-7D118-7I118-7D7325-5(11C18BA54CA8B16C16-)11C18-A54CA8-16C4-23C18-A20C8A26CA8-20C17-2(5F19-7A7-D5-D35A45-)5F19-7(7A7-D5-D35A69-)7E7-D5-2(D35A89-)9(D35A83-D5-)D7A28E83-7(D5-D7A111-)D5-D7E111-22(D5-D118-)5(D5-D18-7A93-)D5-D18-A5BA93-D5-D18-A5-A93-D5-D118-I5-I118-D5-D7325-5(11C18BA54CA8B16C16-)11C18-A54CA8-16C4-23C18-A20C8A26CA8-20C41-9(7A7-D5-D35A69-)7E7-D5-2(D35A89-)9(D35A83-D5-)D7A28E83-7(D5-D7A111-)D5-D7E111-22(D5-D118-)5(D5-D18-7A93-)D5-D18-A5BA93-D5-D18-A5-A93-D5-D118-I5-I118-D5-D7325-5(11C18BA54CA8B16C16-)11C18-A54CA8-16C4-23C18-A20C8A26CA8-20C41-2(7A7-D5-D35A20-3F46-)7(7A7-D5-D35A69-)7E7-D5-2(D35A89-)9(D35A83-D5-)D7A28E83-7(D5-D7A111-)D5-D7E111-22(D5-D118-)2(D5-D18-7A93-)D5-3(D18-7A99-)2(D18-A5BA93-D5-D18-A5-A93-D5-D118-I5-I118-D5-D7325-5(11C18BA54CA8B16C16-)11C18-A54CA8-16C4-23C18-A20C8A26CA8-20C41-2(7A7-D5-D35A20-3F46-)7(7A7-D5-D35A69-)7E7-D5-2(D35A89-)9(D35A83-D5-)D7A28E83-7(D5-D7A111-)D5-D7E111-22(D5-D118-)5(D5-D18-7A93-)D5-)D18-A5BA93-D5-D18-A5-A93-D5-D118-I5-I118-D5-D7325-5(11C18BA54CA8B16C16-)11C18-A54CA8-16C4-23C18-A20C8A26CA8-20C41-9(7A7-7D35A69-)7E7-11(7D35A83-)7D7A28E83-7(7D7A111-)7D7E111-22(7D118-)3(7D18-7A93-)2(3D-3D18-7A93-)3D-3D18-A5BA93-7D18-A5-A93-7D118-7I118-7D7325-5(11C18BA54CA8B16C16-)11C18-A54CA8-16C4-23C18-A20C8A26CA8-20C41-9(56A69-)14E11(42A83-)14A28E83-7(14A111-)7A7E2886-5(7A118-)A5BA118-A5-A7675-5(11C18BA54CA8B16C16-)11C18-A54CA8-16C4-23C18-A20C8A26CA8-20C41-9(56A69-)14E11(42A83-)14A28E83-7(14A111-)A5JA7E120-2(4F121-)4F2512-5(7A118-)A5BA118-A5-A7675-5(84CA8B16C16-)84CA8-16C4-62C8A26CA8-20C41-9(56A69-)14E11(42A83-)14A28E83-7(14A111-)AJ3AJA7E120-2(4F121-)4F2512-5(7A118-)A5BA118-A5-A7675-5(84CA8B16C16-)84CA8-16C4-62C8A26CA8-20C41-9(56A69-)14E11(42A83-)14A28E83-14A4(112-13A)2(111-14A)111-3(AJ)A7E120-2(4F121-)4F2512-5(7A118-)A5BA118-A5-A7675-5(84CA8B16C16-)84CA8-16C4-62C8A26CA8-20C41-9(56A69-)14E11(42A83-)14A28E83-7(14A111-)AJ3AJA7E120-2(4F121-)4F2512-5(7A118-)A5BA118-A5-A7675-5(84CA8B16C16-)84CA8-16C4-62C8A26CA8-20C41-9(56A69-)14E11(42A83-)14A28E83-7(14A111-)A5JA7E120-2(4F121-)4F2512-5(7A118-)A5BA118-A5-A7675-5(84CA8B16C16-)84CA8-16C4-62C8A26CA8-20C41-9(56A69-)14E11(42A83-)2(14A28E83-7(14A111-)7A7E2886-5(7A118-)A5BA118-A5-A7675-5(84CA8B16C16-)84CA8-16C4-62C8A26CA8-20C34-3F4-56A62-3F4-8(56A69-)14E2(42A77-3F3-)9(42A83-))14A28E83-7(14A111-)7A7E2886-5(7A118-)A5BA118-A5-A7675-5(84CA8B16C16-)84CA8-16C4-62C8A26CA8-20C34-3F4-56A12-4F46-3F4-2(56A12-4F53-)6(56A69-)14E2(42A77-3F3-)9(42A83-)14A28E83-14A4(112-13A)2(111-14A)111-2(7A7E2886-5(7A118-)A5BA118-A5-A7675-5(85C2F6B16C16-)85C2F6-16C4-62C8A27C2F6-20C41-2(55A3F10-4F53-)56A12-4F53-6(56A69-)14E11(42A83-)14A28E83-3(14A19-5F87-)2(14A21-3F87-)2(14A111-))7A7E2886-5(7A118-)A5BA118-A5-A7675-5(85C2F6B16C16-)85C2F6-16C4-62C8A27C2F6-20C41-2(55A3F10-4F53-)56A12-4F53-6(56A69-)14E4(42A78-4F-)7(42A79-3F-)14A28E79-3(3F-14A19-5F83-)2(3F-14A21-3F83-)3F-2(14A111-)7A7E2886-5(7A118-)A5BA118-A5-A7675-5(84CA8B16C16-)84CA8-16C4-62C8A26CA8-20C41-9(56A69-)14E4(42A78-4F-)7(42A79-3F-)14A28E79-3(3F-14A19-5F83-)2(3F-14A107-)3F-2(14A111-)7A7E2886-5(7A118-)A5BA118-A5-A7675-5(84CA8B16C16-)84CA8-16C4-62C8A26CA8-20C41-9(56A69-)14E4(42A78-4F-)5(42A79-3F-)2(42A80-2F-)14A28E80-2F-14A19-5F84-2F-2(14A19-5F87-)4(14A111-)7A7E2886-5(7A118-)A5BA118-A5-A7675-5(84CA8B16C16-)84CA8-16C4-62C8A26CA8-20C41-9(56A69-)14E4(42A78-4F-)5(42A79-3F-)2(42A83-)14A28E83-14A4(112-13A)2(111-14A)111-7A7E2886-5(7A118-)A5BA118-A5-A7675-5(84CA8B16C16-)84CA8-16C4-62C8A26CA8-20C41-9(56A69-)14E11(42A83-)14A28E83-7(14A111-)7A7E2886-5(7A118-)A5BA118-A5-A7675-5(84CA8B16C16-)84CA8-16C4-62C8A26CA8-20C36-4(4F-56A64-)4F3(-56A65-3F)-56A66-2F-56A69-14E11(42A83-)14A28E83-7(14A111-)7A7E2886-5(7A118-)A5BA118-A5-A7675-5(58C27A8B16C16-)58C27A8-16C4-62C35A8-20C36-4(4F-56A64-)4F3(-56A65-3F)-56A66-2F-56A69-14E4(42A83-)4(38A-3A83-)3(42A83-)14A28E83-7(14A111-)7A7E2886-5(7A118-)A5BA118-A5-A4992-9A2674-5(56CA36B16C16-)56CA36-16C4-62C7A36-20C14-5(7D15-4F-7A7-7D7A70-)3(7D16-3F-7A7-7D7A70-)7D20-7A7-7D7A70-7I20-7E7-7D7A70-7D34-18(7D7A111-)7D7E111-13(D5-D118-)8(7D118-)7I118-7D6-2(19A106-)19A2(99-26A)99-20A5BA99-20A22(5-A118-A)5-A118-2A3-2A9(118-7A)4(118-3A-3A)3(118-7A)117-9A117-4(7G118-)7G2050-5(56CA36B16C16-)56CA36-16C4-62C7A36-20C14-7D4(15-4F-7A7-7D7A70-D5BD)4(20-7A7-7D7A70-D5BD)20-7A7-7D7A70-I5BI20-7E7-7D7A70-D5-D34-18(7D7A111-)7D7E1736-7D7(118-D5BD)118-I5BI118-D4-BD6-2(19A98-B7-)19A2(98-B26A)98-26BA124-A2868-A5-A16(118-7A)117-9A117-4(7G118-)7G2050-5(56CA36B16C16-)56CA36-16C4-62C7A36-20C14-7D4(15-4F-7A7-7D7A70-D5BD)4(20-7A7-7D7A70-D5BD)20-7A7-7D7A70-I5BI20-7E7-7D7A70-D5-D34-18(7D7A111-)7D7E1736-7D7(118-D5BD)118-I5BI118-D4-BD6-2(19A98-B7-)19A2(98-B26A)98-26BA124-A2993-15(7A118-)7A117-9A117-4(7G118-)7G120-2(3G122-)3G1677-5(56CA6B5F25B16C16-)56CA6-5F25-16C4-62C7A6-5F25-20C14-7D3(20-7A7-7D7A6-5F30-5F24-D5BD)20-7A7-7D7A6-3F34-3F25-2(5BD20-7A7-7D7A71-)2(5BD20-7A7-7D7A70-D)5BD20-7A7-7D7A70-I5BI20-7E7-7D7A70-D5-D34-18(7D7A111-)7D7E1736-7D2(118-D5BD)3(119-5BD)2(118-D5BD)118-I5BI118-D4-BD6-2(19A98-B7-)19A2(98-B26A)98-26BA124-A2993-8(7A118-)7A119-3(5A120-)5A119-2(7A118-)7A117-9A117-4(7G118-)7G120-2(3G122-)3G1677-5(56CA6B5F25B16C16-)56CA6-5F25-16C4-62C7A6-5F25-20C14-7D3(20-7A7-7D7A6-5F30-5F24-D5BD)20-7A7-7D7A6-3F34-3F24-5(D5BD20-7A7-7D7A70-)I5BI20-7E7-7D7A70-D5-D34-18(7D7A111-)7D7E1736-7D7(118-D5BD)118-I5BI118-D4-BD6-2(19A98-B7-)19A2(98-B26A)98-26BA124-A2993-15(7A118-)7A117-9A117-4(7G118-)7G120-2(3G122-)3G1677-5(56CA6B5F25B16C16-)56CA6-5F25-16C4-62C7A6-5F25-20C14-7D3(20-7A7-7D7A6-5F30-5F24-D5BD)20-7A7-7D7A6-3F34-3F24-5(D5BD20-7A7-7D7A70-)I5BI20-7E7-7D7A70-D5-D34-18(7D7A111-)7D7E1736-7D7(118-D5BD)118-I5BI118-D4-BD6-2(19A98-B7-)19A2(98-B26A)98-26BA124-A2868-A5-A16(118-7A)117-9A117-4(7G118-)7G2050-5(56CA6B5F25B16C16-)56CA6-5F25-16C4-62C7A6-5F25-20C14-3(7D20-7A7-7D7A6-5F30-5F24-)7D20-7A7-7D7A6-3F61-3(3D-3D20-7A7-7D7A70-)2(7D20-7A7-7D7A70-)7I20-7E7-7D7A70-7D34-18(7D7A111-)7D7E111-13(D5-D118-)7D7(118-D5BD)118-I5BI118-D5-D6-2(19A106-)19A4(99-26A)22(118-A5-A)118-2A3-2A9(118-7A)4(118-3A-3A)3(118-7A)117-9A117-4(7G118-)7G2050-5(56CA6B5F25B16C16-)56CA6-5F25-16C4-62C7A6-5F25-20C41-3(14A7D7A6-5F30-5F51-)6(14A7D7A97-)8E6A7D7A105-6A7D7A106-5A7D7A107-4A7D7A108-3A7D7A109-2A7D7A110-A7D7A111-D5BD7A111-D5-D11(7A111-7D)7E111-13(D5-D118-)7D7(118-D5BD)118-I5BI118-D5-D5767-9A2674-5(56CA6B5F25B16C16-)56CA6-5F25-16C4-62C7A6-5F25-20C41-3(14A7D7A6-5F86-)6(14A7D7A97-)E5J2E6A7D7A105-6A7D7A106-5A7D7A107-4A7D7A108-3A7D7A109-2A7D7A110-A7D7A111-D5BD7A111-D5-D11(7A111-7D)7E1736-7D7(118-D5BD)118-I5BI118-D5-D8450-5(56CA36B16C16-)56CA36-16C4-62C7A36-20C42-4(13A7D7A97-14A7D7A98-)13A7D7A97-EJ3AJ2E6A7D7A105-6A7D7A106-5A7D7A107-4A7D7A108-3A7D7A109-2A7D7A110-A7D7A111-D5BD7A111-D5-D11(7A111-7D)7E1736-7D7(118-D5BD)118-I5BI118-D5-D8450-5(56CA36B16C16-)56CA36-16C4-62C7A36-20C42-4(13A7D7A97-14A7D7A98-)13A7D7A97-E2(JA)J2E6A7D7A105-6A7D7A106-5A7D7A107-4A7D7A108-3A7D7A109-2A7D7A110-A7D7A111-D5BD7A111-D5-D11(7A111-7D)7E1736-7D2(118-D5BD)3(119-5BD)2(118-D5BD)118-I5BI118-D5-D8450-5(56CA36B16C16-)56CA36-16C4-62C7A36-20C42-4(13A7D7A97-14A7D7A98-)13A7D7A97-EJ3AJ2E6A7D7A105-6A7D7A106-5A7D7A107-4A7D7A108-3A7D7A109-2A7D7A110-A7D7A111-D5BD7A111-D5-D11(7A111-7D)7E1736-7D7(118-D5BD)118-I5BI118-D5-D8450-4(39C4A7D7A31B3F2B16C16-)39C4A7C7A31B3F2B16C16-42CA7C7A31-3F2-16C4-62C7A31-3F2-20C25-3F13-14A7D7A81-3F13-8(14A7D7A97-)E5J2E6A7D7A105-6A7D7A106-5A7D7A107-4A7D7A108-3A7D7A109-2A7D7A110-A7D7A111-D5BD7A111-D5-D11(7A111-7D)7E1736-7D7(118-D5BD)118-I5BI118-D5-D8450-5(39C4A7D7A31B3F2B16C16-)39C4A7D7A31-3F2-16C4-51C4A7D7A31-3F2-20C25-3F13-14A7D7A81-3F13-8(14A7D7A97-)8E6A7D7A105-6A7D7A106-5A7D7A107-4A7D7A108-3A7D7A109-2A7D7A110-A7D7A111-D5BD7A111-D5-D4(7A111-7D)4(3A-3A111-7D)3(7A111-7D)7E111-13(D5-D118-)3(7D118-)3(3D-3D118-)2(7D118-)7I118-7D8450-5(39C49B3F2B16C16-)39C5-5B39-3F2-16C4-51C5-5B39-3F2-20C25-3F11-3F14-5B89-3F11-3F14-15(5B120-)5B12826-2(5(39C54B16C16-)39C54-16C4-51C54-20C39-3F122-3F14720-)2(5(39C16B54C16-)39C16-54C4-51C16-58C14887-)5(39C16B54C16-)39C16-54C4-51C16-58C91-5F22-2F96-5F120-5F14541-5(39C16B54C16-)39C16-54C4-11C5J35C16-58C91-5F12-3F7-2F96-5F12-3F105-5F14541-5(39C16B54C16-)39C16-54C4-11CJ3CJ35C16-58C91-2(5F12-3F105-)5F14541-39C10B5C4(B54C16-39C10B5F)B54C16-39C10-5F-54C4-11CJ3CJ35C10-5F-58C61-2(5F25-5F12-3F75-)5F25-5F14541-39C10B5C4(B54C16-39C10B5F)B54C16-39C10-5F-54C4-11CJ3CJ35C10-5F-58C61-2(5F25-5F90-)5F25-5F14541-39C10B5C4(B54C16-39C10B5F)B54C16-39C10-5F-54C4-11C5J35C2(10-5F-58C61-2(5F120-)5F14571-39C10B5C4(B54C16-39C10B5F)B54C16-39C10-5F-54C4-51C)10-5F-58C61-2(5F120-)5F14571-5(39C16B54C16-)39C16-54C4-51C16-58C14926-4(16B109-)16B183-51C16-58C7(15625-125C)14875-
